<?xml version="1.0" encoding="utf-8"?>
<!-- This URDF was automatically created by SolidWorks to URDF Exporter! Originally created by Stephen Brawner (brawner@gmail.com) 
     Commit Version: 1.5.1-0-g916b5db  Build Version: 1.5.7152.31018
     For more information, please see http://wiki.ros.org/sw_urdf_exporter -->
<robot
  name="final_arm_material">
  <link
    name="base_link">
    <inertial>
      <origin
        xyz="0.0099575 0.010629 0.10027"
        rpy="0 0 0" />
      <mass
        value="25.085" />
      <inertia
        ixx="0.33605"
        ixy="0.00027783"
        ixz="-0.014324"
        iyy="0.33488"
        iyz="-0.0032301"
        izz="0.50135" />
    </inertial>
    <visual>
      <origin
        xyz="0 0 0"
        rpy="0 0 0" />
      <geometry>
        <mesh
          filename="package://final_arm_material/meshes/base_link.STL" />
      </geometry>
      <material
        name="">
        <color
          rgba="0.79216 0.81961 0.93333 1" />
      </material>
    </visual>
    <collision>
      <origin
        xyz="0 0 0"
        rpy="0 0 0" />
      <geometry>
        <mesh
          filename="package://final_arm_material/meshes/base_link.STL" />
      </geometry>
    </collision>
  </link>
  <link
    name="link1">
    <inertial>
      <origin
        xyz="1.3073E-08 -0.54539 -0.039291"
        rpy="0 0 0" />
      <mass
        value="8.6101" />
      <inertia
        ixx="0.17081"
        ixy="-2.9301E-09"
        ixz="9.5086E-09"
        iyy="0.01051"
        iyz="-4.9643E-08"
        izz="0.1699" />
    </inertial>
    <visual>
      <origin
        xyz="0 0 0"
        rpy="0 0 0" />
      <geometry>
        <mesh
          filename="package://final_arm_material/meshes/link1.STL" />
      </geometry>
      <material
        name="">
        <color
          rgba="0.89804 0.91765 0.92941 1" />
      </material>
    </visual>
    <collision>
      <origin
        xyz="0 0 0"
        rpy="0 0 0" />
      <geometry>
        <mesh
          filename="package://final_arm_material/meshes/link1.STL" />
      </geometry>
    </collision>
  </link>
  <joint
    name="joint1"
    type="revolute">
    <origin
      xyz="0.00099395 0.0086075 0.20448"
      rpy="-1.6182 -0.074077 0.7922" />
    <parent
      link="base_link" />
    <child
      link="link1" />
    <axis
      xyz="0 1 0" />
    <limit
      lower="-3.14"
      upper="3.14"
      effort="100"
      velocity="40" />
  </joint>
  <link
    name="link2">
    <inertial>
      <origin
        xyz="-0.10297 -0.0089445 -0.49311"
        rpy="0 0 0" />
      <mass
        value="8.6101" />
      <inertia
        ixx="0.1699"
        ixy="8.6068E-09"
        ixz="-4.9807E-08"
        iyy="0.17075"
        iyz="-0.0029067"
        izz="0.010563" />
    </inertial>
    <visual>
      <origin
        xyz="0 0 0"
        rpy="0 0 0" />
      <geometry>
        <mesh
          filename="package://final_arm_material/meshes/link2.STL" />
      </geometry>
      <material
        name="">
        <color
          rgba="0.89804 0.91765 0.92941 1" />
      </material>
    </visual>
    <collision>
      <origin
        xyz="0 0 0"
        rpy="0 0 0" />
      <geometry>
        <mesh
          filename="package://final_arm_material/meshes/link2.STL" />
      </geometry>
    </collision>
  </link>
  <joint
    name="joint2"
    type="revolute">
    <origin
      xyz="0 -0.67886 0"
      rpy="3.1416 1.5708 0" />
    <parent
      link="link1" />
    <child
      link="link2" />
    <axis
      xyz="-1 0 0" />
    <limit
      lower="-3.14"
      upper="3.14"
      effort="100"
      velocity="40" />
  </joint>
  <link
    name="link3">
    <inertial>
      <origin
        xyz="0.31333 2.8823E-07 -3.0691E-08"
        rpy="0 0 0" />
      <mass
        value="3.6676" />
      <inertia
        ixx="0.0033793"
        ixy="4.9643E-08"
        ixz="-2.9301E-09"
        iyy="0.16377"
        iyz="-9.5086E-09"
        izz="0.16368" />
    </inertial>
    <visual>
      <origin
        xyz="0 0 0"
        rpy="0 0 0" />
      <geometry>
        <mesh
          filename="package://final_arm_material/meshes/link3.STL" />
      </geometry>
      <material
        name="">
        <color
          rgba="0.89804 0.91765 0.92941 1" />
      </material>
    </visual>
    <collision>
      <origin
        xyz="0 0 0"
        rpy="0 0 0" />
      <geometry>
        <mesh
          filename="package://final_arm_material/meshes/link3.STL" />
      </geometry>
    </collision>
  </link>
  <joint
    name="joint3"
    type="revolute">
    <origin
      xyz="0 -0.011365 -0.62656"
      rpy="3.1416 1.4185 -1.5708" />
    <parent
      link="link2" />
    <child
      link="link3" />
    <axis
      xyz="0 -1 0" />
    <limit
      lower="-3.14"
      upper="3.14"
      effort="400"
      velocity="40" />
  </joint>
</robot>