<?xml version="1.0" encoding="utf-8"?>
<!-- This URDF was automatically created by SolidWorks to URDF Exporter! Originally created by Stephen Brawner (brawner@gmail.com) 
     Commit Version: 1.6.0-4-g7f85cfe  Build Version: 1.6.7995.38578
     For more information, please see http://wiki.ros.org/sw_urdf_exporter -->
<robot
  name="larger-arm">
  <link
    name="base_link">
    <inertial>
      <origin
        xyz="-4.38459742593246E-34 0.0907710280373832 -7.13881493679544E-18"
        rpy="0 0 0" />
      <mass
        value="181.521223524418" />
      <inertia
        ixx="5.51881445393319"
        ixy="-1.01727216834597E-32"
        ixz="-1.3215053740922E-32"
        iyy="9.88972581951903"
        iyz="-1.58279641776445E-16"
        izz="5.51881445393319" />
    </inertial>
    <visual>
      <origin
        xyz="0 0 0"
        rpy="0 0 0" />
      <geometry>
        <mesh
          filename="package://larger-arm/meshes/base_link.STL" />
      </geometry>
      <material
        name="">
        <color
          rgba="0.898039215686275 0.917647058823529 0.929411764705882 1" />
      </material>
    </visual>
    <collision>
      <origin
        xyz="0 0 0"
        rpy="0 0 0" />
      <geometry>
        <mesh
          filename="package://larger-arm/meshes/base_link.STL" />
      </geometry>
    </collision>
  </link>
  <link
    name="link0">
    <inertial>
      <origin
        xyz="0.0355178791462037 0.157139821707824 0.0012213422393444"
        rpy="0 0 0" />
      <mass
        value="98.504121014725" />
      <inertia
        ixx="1.9913098332571"
        ixy="-0.692627636667403"
        ixz="-0.0182045043341852"
        iyy="2.9024659203972"
        iyz="-0.0227191786389093"
        izz="3.21938649305015" />
    </inertial>
    <visual>
      <origin
        xyz="0 0 0"
        rpy="0 0 0" />
      <geometry>
        <mesh
          filename="package://larger-arm/meshes/link0.STL" />
      </geometry>
      <material
        name="">
        <color
          rgba="0.898039215686275 0.917647058823529 0.929411764705882 1" />
      </material>
    </visual>
    <collision>
      <origin
        xyz="0 0 0"
        rpy="0 0 0" />
      <geometry>
        <mesh
          filename="package://larger-arm/meshes/link0.STL" />
      </geometry>
    </collision>
  </link>
  <joint
    name="joint0"
    type="revolute">
    <origin
      xyz="0 0 0.2"
      rpy="1.5708 0 0.023788" />
    <parent
      link="base_link" />
    <child
      link="link0" />
    <axis
      xyz="0 1 0" />
    <limit
      lower="-3.14"
      upper="3.14"
      effort="4000"
      velocity="100" />
  </joint>
  <link
    name="link1">
    <inertial>
      <origin
        xyz="-0.592743597484973 -0.0800705727166844 -1.15032171565943E-08"
        rpy="0 0 0" />
      <mass
        value="18.3302560062681" />
      <inertia
        ixx="0.0650826160951017"
        ixy="-1.38814395752879E-09"
        ixz="1.46180244666728E-08"
        iyy="0.743748011122561"
        iyz="-7.51727039990935E-10"
        izz="0.709580436864478" />
    </inertial>
    <visual>
      <origin
        xyz="0 0 0"
        rpy="0 0 0" />
      <geometry>
        <mesh
          filename="package://larger-arm/meshes/link1.STL" />
      </geometry>
      <material
        name="">
        <color
          rgba="0.898039215686275 0.917647058823529 0.929411764705882 1" />
      </material>
    </visual>
    <collision>
      <origin
        xyz="0 0 0"
        rpy="0 0 0" />
      <geometry>
        <mesh
          filename="package://larger-arm/meshes/link1.STL" />
      </geometry>
    </collision>
  </link>
  <joint
    name="joint1"
    type="revolute">
    <origin
      xyz="0.26922 0.38863 0.010954"
      rpy="-1.5708 0 -0.69004" />
    <parent
      link="link0" />
    <child
      link="link1" />
    <axis
      xyz="0 1 0" />
    <limit
      lower="-3.14"
      upper="3.14"
      effort="400"
      velocity="100" />
  </joint>
  <link
    name="link2">
    <inertial>
      <origin
        xyz="0.504677639134419 0.0302850585645254 3.4538243376403E-09"
        rpy="0 0 0" />
      <mass
        value="39.798963686691" />
      <inertia
        ixx="0.163333124103185"
        ixy="-0.0775768385846764"
        ixz="-6.24475532585056E-08"
        iyy="2.92539458142523"
        iyz="-2.71775464633084E-09"
        izz="2.90405278047831" />
    </inertial>
    <visual>
      <origin
        xyz="0 0 0"
        rpy="0 0 0" />
      <geometry>
        <mesh
          filename="package://larger-arm/meshes/link2.STL" />
      </geometry>
      <material
        name="">
        <color
          rgba="0.898039215686275 0.917647058823529 0.929411764705882 1" />
      </material>
    </visual>
    <collision>
      <origin
        xyz="0 0 0"
        rpy="0 0 0" />
      <geometry>
        <mesh
          filename="package://larger-arm/meshes/link2.STL" />
      </geometry>
    </collision>
  </link>
  <joint
    name="joint2"
    type="revolute">
    <origin
      xyz="-1.1822 0 0"
      rpy="3.1416 -1.4337 -3.1416" />
    <parent
      link="link1" />
    <child
      link="link2" />
    <axis
      xyz="0 1 0" />
    <limit
      lower="-3.14"
      upper="3.14"
      effort="400"
      velocity="100" />
  </joint>
  <link
    name="link3">
    <inertial>
      <origin
        xyz="-0.221483196539127 -0.0837151094996036 -8.34939815064217E-08"
        rpy="0 0 0" />
      <mass
        value="10.7350306805923" />
      <inertia
        ixx="0.0375046786503963"
        ixy="-0.0021369481187791"
        ixz="8.73076643111057E-09"
        iyy="0.221795934902841"
        iyz="3.50529072206058E-08"
        izz="0.204712122185334" />
    </inertial>
    <visual>
      <origin
        xyz="0 0 0"
        rpy="0 0 0" />
      <geometry>
        <mesh
          filename="package://larger-arm/meshes/link3.STL" />
      </geometry>
      <material
        name="">
        <color
          rgba="0.898039215686275 0.917647058823529 0.929411764705882 1" />
      </material>
    </visual>
    <collision>
      <origin
        xyz="0 0 0"
        rpy="0 0 0" />
      <geometry>
        <mesh
          filename="package://larger-arm/meshes/link3.STL" />
      </geometry>
    </collision>
  </link>
  <joint
    name="joint3"
    type="revolute">
    <origin
      xyz="1.2107 0.053378 0"
      rpy="0 -1.4003 -3.1416" />
    <parent
      link="link2" />
    <child
      link="link3" />
    <axis
      xyz="0 1 0" />
    <limit
      lower="-3.14"
      upper="3.14"
      effort="400"
      velocity="100" />
  </joint>
  <link
    name="link4">
    <inertial>
      <origin
        xyz="4.44089209850063E-16 0.122823205563208 -6.7168492989822E-15"
        rpy="0 0 0" />
      <mass
        value="2.62527190097231" />
      <inertia
        ixx="0.0283654696913978"
        ixy="-3.83993069275317E-16"
        ixz="-8.67361737988404E-19"
        iyy="0.00529698439534632"
        iyz="-5.21094669150846E-17"
        izz="0.0283654696913978" />
    </inertial>
    <visual>
      <origin
        xyz="0 0 0"
        rpy="0 0 0" />
      <geometry>
        <mesh
          filename="package://larger-arm/meshes/link4.STL" />
      </geometry>
      <material
        name="">
        <color
          rgba="0.898039215686275 0.917647058823529 0.929411764705882 1" />
      </material>
    </visual>
    <collision>
      <origin
        xyz="0 0 0"
        rpy="0 0 0" />
      <geometry>
        <mesh
          filename="package://larger-arm/meshes/link4.STL" />
      </geometry>
    </collision>
  </link>
  <joint
    name="joint4"
    type="revolute">
    <origin
      xyz="-0.65894 -0.084381 0"
      rpy="-3.1416 1.5092 -1.5708" />
    <parent
      link="link3" />
    <child
      link="link4" />
    <axis
      xyz="0 1 0" />
    <limit
      lower="-3.14"
      upper="3.14"
      effort="400"
      velocity="100" />
  </joint>
  <link
    name="end_effector">
    <inertial>
      <origin
        xyz="4.44089209850063E-16 0.0119748663087799 2.52575738102223E-15"
        rpy="0 0 0" />
      <mass
        value="0.0458831332838263" />
      <inertia
        ixx="0.000111089708199407"
        ixy="1.48672811088851E-18"
        ixz="4.98055372985529E-19"
        iyy="0.000219133862355334"
        iyz="-1.68771314740419E-19"
        izz="0.000111089708199408" />
    </inertial>
    <visual>
      <origin
        xyz="0 0 0"
        rpy="0 0 0" />
      <geometry>
        <mesh
          filename="package://larger-arm/meshes/end_effector.STL" />
      </geometry>
      <material
        name="">
        <color
          rgba="0.792156862745098 0.819607843137255 0.933333333333333 1" />
      </material>
    </visual>
    <collision>
      <origin
        xyz="0 0 0"
        rpy="0 0 0" />
      <geometry>
        <mesh
          filename="package://larger-arm/meshes/end_effector.STL" />
      </geometry>
    </collision>
  </link>
  <joint
    name="joint5"
    type="revolute">
    <origin
      xyz="0 0.2695 0"
      rpy="0 -0.20586 0" />
    <parent
      link="link4" />
    <child
      link="end_effector" />
    <axis
      xyz="0 1 0" />
    <limit
      lower="-3.14"
      upper="3.14"
      effort="4000"
      velocity="100" />
  </joint>
</robot>
