<?xml version="1.0" encoding="utf-8"?>
<!-- This URDF was automatically created by SolidWorks to URDF Exporter! Originally created by Stephen Brawner (brawner@gmail.com) 
     Commit Version: 1.6.0-4-g7f85cfe  Build Version: 1.6.7995.38578
     For more information, please see http://wiki.ros.org/sw_urdf_exporter -->
<robot
  name="Assem1_universal">
  <link
    name="base_link">
    <inertial>
      <origin
        xyz="0.296485796835353 -0.611898974441144 0.318944214640172"
        rpy="0 0 0" />
      <mass
        value="181.521223524418" />
      <inertia
        ixx="5.51881445393319"
        ixy="5.68950562251315E-32"
        ixz="-1.30000271246138E-31"
        iyy="5.51881445393319"
        iyz="4.25911933290988E-16"
        izz="9.88972581951903" />
    </inertial>
    <visual>
      <origin
        xyz="0 0 0"
        rpy="0 0 0" />
      <geometry>
        <mesh
          filename="package://Assem1_universal/meshes/base_link.STL" />
      </geometry>
      <material
        name="">
        <color
          rgba="0.898039215686275 0.917647058823529 0.929411764705882 1" />
      </material>
    </visual>
    <collision>
      <origin
        xyz="0 0 0"
        rpy="0 0 0" />
      <geometry>
        <mesh
          filename="package://Assem1_universal/meshes/base_link.STL" />
      </geometry>
    </collision>
  </link>
  <link
    name="link1">
    <inertial>
      <origin
        xyz="0.0507206032685569 0.188259194798284 0.00110984147920914"
        rpy="0 0 0" />
      <mass
        value="58.929995324725" />
      <inertia
        ixx="1.30216781385276"
        ixy="-0.481625078609562"
        ixz="-0.0043790215764947"
        iyy="2.05240641336218"
        iyz="-0.00797418189249532"
        izz="2.36610889031325" />
    </inertial>
    <visual>
      <origin
        xyz="0 0 0"
        rpy="0 0 0" />
      <geometry>
        <mesh
          filename="package://Assem1_universal/meshes/link1.STL" />
      </geometry>
      <material
        name="">
        <color
          rgba="0.898039215686275 0.917647058823529 0.929411764705882 1" />
      </material>
    </visual>
    <collision>
      <origin
        xyz="0 0 0"
        rpy="0 0 0" />
      <geometry>
        <mesh
          filename="package://Assem1_universal/meshes/link1.STL" />
      </geometry>
    </collision>
  </link>
  <joint
    name="joint 0"
    type="revolute">
    <origin
      xyz="0.29649 -0.6119 0.42817"
      rpy="1.5708 0 -1.2631" />
    <parent
      link="base_link" />
    <child
      link="link1" />
    <axis
      xyz="0 1 0" />
    <limit
      lower="-3.14"
      upper="3.14"
      effort="0"
      velocity="0" />
  </joint>
  <link
    name="link2">
    <inertial>
      <origin
        xyz="-0.592184811265197 -0.0908315253787347 -7.30949339944331E-09"
        rpy="0 0 0" />
      <mass
        value="14.6892193907076" />
      <inertia
        ixx="0.058482861182971"
        ixy="4.25759570134299E-09"
        ixz="-2.73676821569563E-08"
        iyy="0.430930332041447"
        iyz="3.77585007010905E-09"
        izz="0.396763126204725" />
    </inertial>
    <visual>
      <origin
        xyz="0 0 0"
        rpy="0 0 0" />
      <geometry>
        <mesh
          filename="package://Assem1_universal/meshes/link2.STL" />
      </geometry>
      <material
        name="">
        <color
          rgba="0.898039215686275 0.917647058823529 0.929411764705882 1" />
      </material>
    </visual>
    <collision>
      <origin
        xyz="0 0 0"
        rpy="0 0 0" />
      <geometry>
        <mesh
          filename="package://Assem1_universal/meshes/link2.STL" />
      </geometry>
    </collision>
  </link>
  <joint
    name="joint 1"
    type="revolute">
    <origin
      xyz="0.26922 0.38863 0"
      rpy="-1.5708 0 -2.1112" />
    <parent
      link="link1" />
    <child
      link="link2" />
    <axis
      xyz="0 1 0" />
    <limit
      lower="-3.14"
      upper="3.14"
      effort="0"
      velocity="0" />
  </joint>
  <link
    name="link 3">
    <inertial>
      <origin
        xyz="0.589010391335981 0.0201110258263087 -0.000885747449043572"
        rpy="0 0 0" />
      <mass
        value="23.5729079118835" />
      <inertia
        ixx="0.11704748465171"
        ixy="-0.0290376210439535"
        ixz="-0.00344333529009955"
        iyy="1.59119945867572"
        iyz="0.000125109454823913"
        izz="1.55992616436486" />
    </inertial>
    <visual>
      <origin
        xyz="0 0 0"
        rpy="0 0 0" />
      <geometry>
        <mesh
          filename="package://Assem1_universal/meshes/link 3.STL" />
      </geometry>
      <material
        name="">
        <color
          rgba="0.898039215686275 0.917647058823529 0.929411764705882 1" />
      </material>
    </visual>
    <collision>
      <origin
        xyz="0 0 0"
        rpy="0 0 0" />
      <geometry>
        <mesh
          filename="package://Assem1_universal/meshes/link 3.STL" />
      </geometry>
    </collision>
  </link>
  <joint
    name="joint 2"
    type="revolute">
    <origin
      xyz="-1.1822 0 0"
      rpy="3.1416 -0.19008 -3.1416" />
    <parent
      link="link2" />
    <child
      link="link 3" />
    <axis
      xyz="0 1 0" />
    <limit
      lower="-3.14"
      upper="3.14"
      effort="0"
      velocity="0" />
  </joint>
  <link
    name="link 4">
    <inertial>
      <origin
        xyz="-0.00350901194985509 0.444290690237279 -0.0699239602138977"
        rpy="0 0 0" />
      <mass
        value="4.7422733749791" />
      <inertia
        ixx="0.0668146172266336"
        ixy="6.6343183442658E-05"
        ixz="0.000309777723202941"
        iyy="0.0189783890803951"
        iyz="0.00078173736771283"
        izz="0.0749808653607735" />
    </inertial>
    <visual>
      <origin
        xyz="0 0 0"
        rpy="0 0 0" />
      <geometry>
        <mesh
          filename="package://Assem1_universal/meshes/link 4.STL" />
      </geometry>
      <material
        name="">
        <color
          rgba="0.792156862745098 0.819607843137255 0.933333333333333 1" />
      </material>
    </visual>
    <collision>
      <origin
        xyz="0 0 0"
        rpy="0 0 0" />
      <geometry>
        <mesh
          filename="package://Assem1_universal/meshes/link 4.STL" />
      </geometry>
    </collision>
  </link>
  <joint
    name="joint 3"
    type="revolute">
    <origin
      xyz="1.2508 0.056145 0"
      rpy="-1.5304 0.68813 -3.0781" />
    <parent
      link="link 3" />
    <child
      link="link 4" />
    <axis
      xyz="0.049037 0 0.9988" />
    <limit
      lower="-3.14"
      upper="3.14"
      effort="0"
      velocity="0" />
  </joint>
  <link
    name="link 5">
    <inertial>
      <origin
        xyz="-1.15186862714722E-07 -0.00290333942894883 -0.00103896172427165"
        rpy="0 0 0" />
      <mass
        value="0.761354400003499" />
      <inertia
        ixx="0.00112625497805474"
        ixy="-2.41542571835225E-09"
        ixz="9.63054909442008E-10"
        iyy="0.00124823563907516"
        iyz="1.65024365820752E-07"
        izz="0.00106990091896965" />
    </inertial>
    <visual>
      <origin
        xyz="0 0 0"
        rpy="0 0 0" />
      <geometry>
        <mesh
          filename="package://Assem1_universal/meshes/link 5.STL" />
      </geometry>
      <material
        name="">
        <color
          rgba="0.898039215686275 0.917647058823529 0.929411764705882 1" />
      </material>
    </visual>
    <collision>
      <origin
        xyz="0 0 0"
        rpy="0 0 0" />
      <geometry>
        <mesh
          filename="package://Assem1_universal/meshes/link 5.STL" />
      </geometry>
    </collision>
  </link>
  <joint
    name="joint 4"
    type="revolute">
    <origin
      xyz="0 1.0454 -0.070575"
      rpy="1.5708 -0.4488 1.5708" />
    <parent
      link="link 4" />
    <child
      link="link 5" />
    <axis
      xyz="0 0 1" />
    <limit
      lower="-3.14"
      upper="3.14"
      effort="0"
      velocity="0" />
  </joint>
  <link
    name="link6">
    <inertial>
      <origin
        xyz="0 0.0220625297833468 1.50990331349021E-14"
        rpy="0 0 0" />
      <mass
        value="0.2351717720661" />
      <inertia
        ixx="0.00010836728862395"
        ixy="9.90181515340277E-19"
        ixz="3.3881317890172E-21"
        iyy="0.000206387616600977"
        iyz="4.02340649945793E-19"
        izz="0.00010836728862395" />
    </inertial>
    <visual>
      <origin
        xyz="0 0 0"
        rpy="0 0 0" />
      <geometry>
        <mesh
          filename="package://Assem1_universal/meshes/link6.STL" />
      </geometry>
      <material
        name="">
        <color
          rgba="0.898039215686275 0.917647058823529 0.929411764705882 1" />
      </material>
    </visual>
    <collision>
      <origin
        xyz="0 0 0"
        rpy="0 0 0" />
      <geometry>
        <mesh
          filename="package://Assem1_universal/meshes/link6.STL" />
      </geometry>
    </collision>
  </link>
  <joint
    name="joint 5"
    type="revolute">
    <origin
      xyz="0 0.021359 -0.00096493"
      rpy="0 0.75918 0" />
    <parent
      link="link 5" />
    <child
      link="link6" />
    <axis
      xyz="0 1 0" />
    <limit
      lower="-3.14"
      upper="3.14"
      effort="0"
      velocity="0" />
  </joint>
</robot>